<?xml version='1.0' encoding='utf-8'?>
<robot name="ar10">
  <link name="wrist_plate">
    <visual>
      <geometry>
        <mesh filename="package://ar10_description/meshes/wrist plate.STL" scale=".001 .001 .001" />
      </geometry>
      <origin xyz="-.03645 .0291 -.002" rpy="1.57 0 0" />
      <material name="blue">
        <color rgba=".1 .1 .4 1" />
      </material>
    </visual>
    <collision>
      <geometry>
        <cylinder length=".002" radius=".06" />
      </geometry>
    </collision>
    <inertial>
      <mass value="0.08" />
      <inertia ixx="0.00024" ixy="0.0" ixz="0.0" iyy="0.00024" iyz="0.0" izz="0.00048" />
    </inertial>
  </link>
  <link name="circuit_support">
    <visual>
      <geometry>
        <box size=".05 .05 .05" />
      </geometry>
      <origin xyz="0 0 .025" />
      <material name="black">
        <color rgba=".1 .1 .1 1" />
      </material>
    </visual>
    <collision>
      <geometry>
        <box size=".05 .05 .05" />
      </geometry>
      <origin xyz="0 0 .025" />
    </collision>
    <inertial>
      <mass value="0.005" />
      <inertia ixx="1e-07" ixy="0.0" ixz="0.0" iyy="1e-07" iyz="0.0" izz="1e-07" />
    </inertial>
  </link>
  <joint name="wrist_plate_to_circuit_support" type="fixed">
    <parent link="wrist_plate" />
    <child link="circuit_support" />
    <origin xyz="0 0 0" />
  </joint>
  <link name="palm">
    <visual>
      <geometry>
        <mesh filename="package://ar10_description/meshes/Palm -RIGHT.STL" scale=".001 .001 .001" />
      </geometry>
      <origin xyz="-.05675 .005 .002" rpy="1.57 0 0" />
      <material name="blue" />
    </visual>
    <collision>
      <geometry>
        <mesh filename="package://ar10_description/meshes/Palm -RIGHT.STL" scale=".001 .001 .001" />
      </geometry>
      <origin xyz="-.05675 .005 .002" rpy="1.57 0 0" />
    </collision>
    <inertial>
      <mass value="0.35" />
      <inertia ixx="0.0002" ixy="0.0" ixz="0.0" iyy="0.00043" iyz="0.0" izz="0.00061" />
    </inertial>
  </link>
  <joint name="circuit_support_to_palm" type="fixed">
    <parent link="circuit_support" />
    <child link="palm" />
    <origin xyz="0 .0155 .04815" />
  </joint>
  <link name="rb1">
    <visual>
      <geometry>
        <mesh filename="package://ar10_description/meshes/rod-end-2mm-BLUE.STL" scale=".001 .001 .001" />
      </geometry>
      <origin xyz="-.002 -.00375 .00375" rpy="3.14 0 1.57" />
      <material name="lightblue">
        <color rgba=".3 .5 .7 1" />
      </material>
    </visual>
    <collision>
      <geometry>
        <mesh filename="package://ar10_description/meshes/rod-end-2mm-BLUE.STL" scale=".001 .001 .001" />
      </geometry>
      <origin xyz="-.002 -.00375 .00375" rpy="3.14 0 1.57" />
    </collision>
    <inertial>
      <mass value="0.005" />
      <inertia ixx="1e-07" ixy="0.0" ixz="0.0" iyy="1e-07" iyz="0.0" izz="1e-07" />
    </inertial>
  </link>
  <joint name="rb1_to_palm" type="fixed">
    <parent link="palm" />
    <child link="rb1" />
    <origin xyz=".0235 -.012 .08" />
  </joint>
  <link name="rb2">
    <visual>
      <geometry>
        <mesh filename="package://ar10_description/meshes/rod-end-2mm-BLUE.STL" scale=".001 .001 .001" />
      </geometry>
      <origin xyz="-.002 -.00375 .00375" rpy="3.14 0 1.57" />
      <material name="lightblue" />
    </visual>
    <collision>
      <geometry>
        <mesh filename="package://ar10_description/meshes/rod-end-2mm-BLUE.STL" scale=".001 .001 .001" />
      </geometry>
      <origin xyz="-.002 -.00375 .00375" rpy="3.14 0 1.57" />
    </collision>
    <inertial>
      <mass value="0.005" />
      <inertia ixx="1e-07" ixy="0.0" ixz="0.0" iyy="1e-07" iyz="0.0" izz="1e-07" />
    </inertial>
  </link>
  <joint name="rb2_to_palm" type="fixed">
    <parent link="palm" />
    <child link="rb2" />
    <origin xyz=".0105 -.012 .08" />
  </joint>
  <link name="rb3">
    <visual>
      <geometry>
        <mesh filename="package://ar10_description/meshes/rod-end-2mm-BLUE.STL" scale=".001 .001 .001" />
      </geometry>
      <origin xyz="-.002 -.00375 .00375" rpy="3.14 0 1.57" />
      <material name="lightblue" />
    </visual>
    <collision>
      <geometry>
        <mesh filename="package://ar10_description/meshes/rod-end-2mm-BLUE.STL" scale=".001 .001 .001" />
      </geometry>
      <origin xyz="-.002 -.00375 .00375" rpy="3.14 0 1.57" />
    </collision>
    <inertial>
      <mass value="0.005" />
      <inertia ixx="1e-07" ixy="0.0" ixz="0.0" iyy="1e-07" iyz="0.0" izz="1e-07" />
    </inertial>
  </link>
  <joint name="rb3_to_palm" type="fixed">
    <parent link="palm" />
    <child link="rb3" />
    <origin xyz=".0027 -.012 .09" />
  </joint>
  <link name="rb4">
    <visual>
      <geometry>
        <mesh filename="package://ar10_description/meshes/rod-end-2mm-BLUE.STL" scale=".001 .001 .001" />
      </geometry>
      <origin xyz="-.002 -.00375 .00375" rpy="3.14 0 1.57" />
      <material name="lightblue" />
    </visual>
    <collision>
      <geometry>
        <mesh filename="package://ar10_description/meshes/rod-end-2mm-BLUE.STL" scale=".001 .001 .001" />
      </geometry>
      <origin xyz="-.002 -.00375 .00375" rpy="3.14 0 1.57" />
    </collision>
    <inertial>
      <mass value="0.005" />
      <inertia ixx="1e-07" ixy="0.0" ixz="0.0" iyy="1e-07" iyz="0.0" izz="1e-07" />
    </inertial>
  </link>
  <joint name="rb4_to_palm" type="fixed">
    <parent link="palm" />
    <child link="rb4" />
    <origin xyz="-.011 -.012 .09" />
  </joint>
  <link name="rb5">
    <visual>
      <geometry>
        <mesh filename="package://ar10_description/meshes/rod-end-2mm-BLUE.STL" scale=".001 .001 .001" />
      </geometry>
      <origin xyz="-.002 -.00375 .00375" rpy="3.14 0 1.57" />
      <material name="lightblue" />
    </visual>
    <collision>
      <geometry>
        <mesh filename="package://ar10_description/meshes/rod-end-2mm-BLUE.STL" scale=".001 .001 .001" />
      </geometry>
      <origin xyz="-.002 -.00375 .00375" rpy="3.14 0 1.57" />
    </collision>
    <inertial>
      <mass value="0.005" />
      <inertia ixx="1e-07" ixy="0.0" ixz="0.0" iyy="1e-07" iyz="0.0" izz="1e-07" />
    </inertial>
  </link>
  <joint name="rb5_to_palm" type="fixed">
    <parent link="palm" />
    <child link="rb5" />
    <origin xyz="-.019 -.012 .1" />
  </joint>
  <link name="rb6">
    <visual>
      <geometry>
        <mesh filename="package://ar10_description/meshes/rod-end-2mm-BLUE.STL" scale=".001 .001 .001" />
      </geometry>
      <origin xyz="-.002 -.00375 .00375" rpy="3.14 0 1.57" />
      <material name="lightblue" />
    </visual>
    <collision>
      <geometry>
        <mesh filename="package://ar10_description/meshes/rod-end-2mm-BLUE.STL" scale=".001 .001 .001" />
      </geometry>
      <origin xyz="-.002 -.00375 .00375" rpy="3.14 0 1.57" />
    </collision>
    <inertial>
      <mass value="0.005" />
      <inertia ixx="1e-07" ixy="0.0" ixz="0.0" iyy="1e-07" iyz="0.0" izz="1e-07" />
    </inertial>
  </link>
  <joint name="rb6_to_palm" type="fixed">
    <parent link="palm" />
    <child link="rb6" />
    <origin xyz="-.032 -.012 .1" />
  </joint>
  <link name="rb7">
    <visual>
      <geometry>
        <mesh filename="package://ar10_description/meshes/rod-end-2mm-BLUE.STL" scale=".001 .001 .001" />
      </geometry>
      <origin xyz="-.002 -.00375 .00375" rpy="3.14 0 1.57" />
      <material name="lightblue" />
    </visual>
    <collision>
      <geometry>
        <mesh filename="package://ar10_description/meshes/rod-end-2mm-BLUE.STL" scale=".001 .001 .001" />
      </geometry>
      <origin xyz="-.002 -.00375 .00375" rpy="3.14 0 1.57" />
    </collision>
    <inertial>
      <mass value="0.005" />
      <inertia ixx="1e-07" ixy="0.0" ixz="0.0" iyy="1e-07" iyz="0.0" izz="1e-07" />
    </inertial>
  </link>
  <joint name="rb7_to_palm" type="fixed">
    <parent link="palm" />
    <child link="rb7" />
    <origin xyz="-.04 -.012 .095" />
  </joint>
  <link name="rb8">
    <visual>
      <geometry>
        <mesh filename="package://ar10_description/meshes/rod-end-2mm-BLUE.STL" scale=".001 .001 .001" />
      </geometry>
      <origin xyz="-.002 -.00375 .00375" rpy="3.14 0 1.57" />
      <material name="lightblue" />
    </visual>
    <collision>
      <geometry>
        <mesh filename="package://ar10_description/meshes/rod-end-2mm-BLUE.STL" scale=".001 .001 .001" />
      </geometry>
      <origin xyz="-.002 -.00375 .00375" rpy="3.14 0 1.57" />
    </collision>
    <inertial>
      <mass value="0.005" />
      <inertia ixx="1e-07" ixy="0.0" ixz="0.0" iyy="1e-07" iyz="0.0" izz="1e-07" />
    </inertial>
  </link>
  <joint name="rb8_to_palm" type="fixed">
    <parent link="palm" />
    <child link="rb8" />
    <origin xyz="-.053 -.012 .095" />
  </joint>
  <link name="rb9">
    <visual>
      <geometry>
        <mesh filename="package://ar10_description/meshes/rod-end-2mm-BLUE.STL" scale=".001 .001 .001" />
      </geometry>
      <origin xyz="-.002 -.00375 .00375" rpy="3.14 0 1.57" />
      <material name="lightblue" />
    </visual>
    <collision>
      <geometry>
        <mesh filename="package://ar10_description/meshes/rod-end-2mm-BLUE.STL" scale=".001 .001 .001" />
      </geometry>
      <origin xyz="-.002 -.00375 .00375" rpy="3.14 0 1.57" />
    </collision>
    <inertial>
      <mass value="0.005" />
      <inertia ixx="1e-07" ixy="0.0" ixz="0.0" iyy="1e-07" iyz="0.0" izz="1e-07" />
    </inertial>
  </link>
  <joint name="rb9_to_palm" type="fixed">
    <parent link="palm" />
    <child link="rb9" />
    <origin xyz="-.039 -.012 .0295" rpy="0 -1.29 0" />
  </joint>
  <link name="rb10">
    <visual>
      <geometry>
        <mesh filename="package://ar10_description/meshes/rod-end-2mm-BLUE.STL" scale=".001 .001 .001" />
      </geometry>
      <origin xyz="-.002 -.00375 .00375" rpy="3.14 0 1.57" />
      <material name="lightblue" />
    </visual>
    <collision>
      <geometry>
        <mesh filename="package://ar10_description/meshes/rod-end-2mm-BLUE.STL" scale=".001 .001 .001" />
      </geometry>
      <origin xyz="-.002 -.00375 .00375" rpy="3.14 0 1.57" />
    </collision>
    <inertial>
      <mass value="0.005" />
      <inertia ixx="1e-07" ixy="0.0" ixz="0.0" iyy="1e-07" iyz="0.0" izz="1e-07" />
    </inertial>
  </link>
  <joint name="rb10_to_palm" type="fixed">
    <parent link="palm" />
    <child link="rb10" />
    <origin xyz="-.041 -.012 .022" rpy="0 -1.29 0" />
  </joint>
  <link name="rb11">
    <visual>
      <geometry>
        <mesh filename="package://ar10_description/meshes/rod-end-2mm-BLUE.STL" scale=".001 .001 .001" />
      </geometry>
      <origin xyz="-.002 .00375 .00375" rpy="3.14 1.57 1.57" />
      <material name="lightblue" />
    </visual>
    <collision>
      <geometry>
        <mesh filename="package://ar10_description/meshes/rod-end-2mm-BLUE.STL" scale=".001 .001 .001" />
      </geometry>
      <origin xyz="-.002 -.00375 .00375" rpy="3.14 1.57 1.57" />
    </collision>
    <inertial>
      <mass value="0.005" />
      <inertia ixx="1e-07" ixy="0.0" ixz="0.0" iyy="1e-07" iyz="0.0" izz="1e-07" />
    </inertial>
  </link>
  <link name="rb12">
    <visual>
      <geometry>
        <mesh filename="package://ar10_description/meshes/rod-end-2mm-BLUE.STL" scale=".001 .001 .001" />
      </geometry>
      <origin xyz="-.002 .00375 .00375" rpy="3.14 1.57 1.57" />
      <material name="lightblue" />
    </visual>
    <collision>
      <geometry>
        <mesh filename="package://ar10_description/meshes/rod-end-2mm-BLUE.STL" scale=".001 .001 .001" />
      </geometry>
      <origin xyz="-.002 -.00375 .00375" rpy="3.14 1.57 1.57" />
    </collision>
    <inertial>
      <mass value="0.005" />
      <inertia ixx="1e-07" ixy="0.0" ixz="0.0" iyy="1e-07" iyz="0.0" izz="1e-07" />
    </inertial>
  </link>
  <link name="finger1.1a">
    <visual>
      <geometry>
        <mesh filename="package://ar10_description/meshes/45mm 3 hole.STL" scale=".001 .001 .001" />
      </geometry>
      <origin xyz="0 -.00325 .0135" rpy="-1.57 1.57 0" />
      <material name="blue">
        <color rgba=".1 .1 .4 1" />
      </material>
    </visual>
    <collision>
      <geometry>
        <mesh filename="package://ar10_description/meshes/45mm 3 hole.STL" scale=".001 .001 .001" />
      </geometry>
      <origin xyz="0 -.00325 .0135" rpy="-1.57 1.57 0" />
    </collision>
    <visual>
      <geometry>
        <mesh filename="package://ar10_description/meshes/45mm 3 hole.STL" scale=".001 .001 .001" />
      </geometry>
      <origin xyz="-0.01 -.00325 .0135" rpy="-1.57 1.57 0" />
      <material name="blue" />
    </visual>
    <collision>
      <geometry>
        <mesh filename="package://ar10_description/meshes/45mm 3 hole.STL" scale=".001 .001 .001" />
      </geometry>
      <origin xyz="-0.01 -.00325 .0135" rpy="-1.57 1.57 0" />
    </collision>
    <inertial>
      <mass value="0.02" />
      <inertia ixx="7.1e-07" ixy="0.0" ixz="0.0" iyy="3.4e-06" iyz="0.0" izz="4e-06" />
    </inertial>
  </link>
  <joint name="servo2" type="revolute">
    <axis xyz="-1 0 0" />
    <limit effort="0.42" lower="0.17" upper="1.57" velocity="0.5" />
    <parent link="rb1" />
    <child link="finger1.1a" />
    <origin xyz="-.002 0 0" rpy="3.14 0 0" />
  </joint>
  <link name="finger1.1b">
    <visual>
      <geometry>
        <mesh filename="package://ar10_description/meshes/30mmROSFULL.STL" scale=".001 .001 .001" />
      </geometry>
      <origin xyz="0 -.0035 .0125" rpy="-1.57 1.57 0" />
      <material name="blue" />
    </visual>
    <collision>
      <geometry>
        <mesh filename="package://ar10_description/meshes/30mmROSFULL.STL" scale=".001 .001 .001" />
      </geometry>
      <origin xyz="0 -.0035 .0125" rpy="-1.57 1.57 0" />
    </collision>
    <visual>
      <geometry>
        <mesh filename="package://ar10_description/meshes/30mmROSFULL.STL" scale=".001 .001 .001" />
      </geometry>
      <origin xyz="-0.01 -.0035 .0125" rpy="-1.57 1.57 0" />
      <material name="blue" />
    </visual>
    <collision>
      <geometry>
        <mesh filename="package://ar10_description/meshes/30mmROSFULL.STL" scale=".001 .001 .001" />
      </geometry>
      <origin xyz="-0.01 -.0035 .0125" rpy="-1.57 1.57 0" />
    </collision>
    <inertial>
      <mass value="0.015" />
      <inertia ixx="5.3e-07" ixy="0.0" ixz="0.0" iyy="1.2e-06" iyz="0.0" izz="1.6e-06" />
    </inertial>
  </link>
  <joint name="servo3" type="revolute">
    <axis xyz="-1 0 0" />
    <limit effort="0.42" lower="0.17" upper="1.57" velocity="0.5" />
    <parent link="finger1.1a" />
    <child link="finger1.1b" />
    <origin xyz=".001 0 -.045" rpy="0 0 0" />
  </joint>
  <link name="finger1.1c">
    <visual>
      <geometry>
        <mesh filename="package://ar10_description/meshes/Fingertip.STL" scale=".001 .001 .001" />
      </geometry>
      <origin xyz="0 -.0035 .00825" rpy="-1.57 1.57 0" />
      <material name="blue" />
    </visual>
    <collision>
      <geometry>
        <mesh filename="package://ar10_description/meshes/Fingertip.STL" scale=".001 .001 .001" />
      </geometry>
      <origin xyz="0 -.0035 .00825" rpy="-1.57 1.57 0" />
    </collision>
    <visual>
      <geometry>
        <mesh filename="package://ar10_description/meshes/Fingertip.STL" scale=".001 .001 .001" />
      </geometry>
      <origin xyz="-0.01 -.0035 .00825" rpy="-1.57 1.57 0" />
      <material name="blue" />
    </visual>
    <collision>
      <geometry>
        <mesh filename="package://ar10_description/meshes/Fingertip.STL" scale=".001 .001 .001" />
      </geometry>
      <origin xyz="-0.01 -.0035 .00825" rpy="-1.57 1.57 0" />
    </collision>
    <inertial>
      <mass value="0.008" />
      <inertia ixx="1.7e-07" ixy="0.0" ixz="0.0" iyy="2.8e-07" iyz="0.0" izz="4.2e-07" />
    </inertial>
  </link>
  <joint name="tip1" type="revolute">
    <axis xyz="-1 0 0" />
    <limit effort="0.42" lower="0.17" upper="1.57" velocity="0.5" />
    <parent link="finger1.1b" />
    <child link="finger1.1c" />
    <origin xyz="-.001 0 -.03" rpy="0 0 0" />
    <mimic joint="servo3" multiplier=".49" offset=".16" />
  </joint>
  <link name="fingertip1">
    <visual>
      <geometry>
        <mesh filename="package://ar10_description/meshes/fingertip-v9.STL" scale=".001 .001 .001" />
      </geometry>
      <origin xyz="-.009715 .011 -.015" rpy="1.57 0 0" />
      <material name="black">
        <color rgba=".1 .1 .1 1" />
      </material>
    </visual>
    <collision>
      <geometry>
        <mesh filename="package://ar10_description/meshes/fingertip-v9.STL" scale=".001 .001 .001" />
      </geometry>
      <origin xyz="-.009715 .011 -.015" rpy="1.57 0 0" />
    </collision>
    <inertial>
      <mass value="0.003" />
      <inertia ixx="3.5e-08" ixy="0.0" ixz="0.0" iyy="5.2e-08" iyz="0.0" izz="6.9e-08" />
    </inertial>
  </link>
  <joint name="ee1" type="fixed">
    <parent link="finger1.1c" />
    <child link="fingertip1" />
    <origin xyz="-.005 0 -.02" rpy="0 0 0" />
  </joint>
  <link name="finger2.1a">
    <visual>
      <geometry>
        <mesh filename="package://ar10_description/meshes/45mm 3 hole.STL" scale=".001 .001 .001" />
      </geometry>
      <origin xyz="0 -.00325 .0135" rpy="-1.57 1.57 0" />
      <material name="blue" />
    </visual>
    <collision>
      <geometry>
        <mesh filename="package://ar10_description/meshes/45mm 3 hole.STL" scale=".001 .001 .001" />
      </geometry>
      <origin xyz="0 -.00325 .0135" rpy="-1.57 1.57 0" />
    </collision>
    <visual>
      <geometry>
        <mesh filename="package://ar10_description/meshes/45mm 3 hole.STL" scale=".001 .001 .001" />
      </geometry>
      <origin xyz="-0.01 -.00325 .0135" rpy="-1.57 1.57 0" />
      <material name="blue" />
    </visual>
    <collision>
      <geometry>
        <mesh filename="package://ar10_description/meshes/45mm 3 hole.STL" scale=".001 .001 .001" />
      </geometry>
      <origin xyz="-0.01 -.00325 .0135" rpy="-1.57 1.57 0" />
    </collision>
    <inertial>
      <mass value="0.02" />
      <inertia ixx="7.1e-07" ixy="0.0" ixz="0.0" iyy="3.4e-06" iyz="0.0" izz="4e-06" />
    </inertial>
  </link>
  <joint name="servo4" type="revolute">
    <axis xyz="-1 0 0" />
    <limit effort="0.42" lower="0.17" upper="1.57" velocity="0.5" />
    <parent link="rb3" />
    <child link="finger2.1a" />
    <origin xyz="-.002 0 0" rpy="3.14 0 0" />
  </joint>
  <link name="finger2.1b">
    <visual>
      <geometry>
        <mesh filename="package://ar10_description/meshes/30mmROSFULL.STL" scale=".001 .001 .001" />
      </geometry>
      <origin xyz="0 -.0035 .0125" rpy="-1.57 1.57 0" />
      <material name="blue" />
    </visual>
    <collision>
      <geometry>
        <mesh filename="package://ar10_description/meshes/30mmROSFULL.STL" scale=".001 .001 .001" />
      </geometry>
      <origin xyz="0 -.0035 .0125" rpy="-1.57 1.57 0" />
    </collision>
    <visual>
      <geometry>
        <mesh filename="package://ar10_description/meshes/30mmROSFULL.STL" scale=".001 .001 .001" />
      </geometry>
      <origin xyz="-0.01 -.0035 .0125" rpy="-1.57 1.57 0" />
      <material name="blue" />
    </visual>
    <collision>
      <geometry>
        <mesh filename="package://ar10_description/meshes/30mmROSFULL.STL" scale=".001 .001 .001" />
      </geometry>
      <origin xyz="-0.01 -.0035 .0125" rpy="-1.57 1.57 0" />
    </collision>
    <inertial>
      <mass value="0.015" />
      <inertia ixx="5.3e-07" ixy="0.0" ixz="0.0" iyy="1.2e-06" iyz="0.0" izz="1.6e-06" />
    </inertial>
  </link>
  <joint name="servo5" type="revolute">
    <axis xyz="-1 0 0" />
    <limit effort="0.42" lower="0.17" upper="1.57" velocity="0.5" />
    <parent link="finger2.1a" />
    <child link="finger2.1b" />
    <origin xyz=".001 0 -.045" rpy="0 0 0" />
  </joint>
  <link name="finger2.1c">
    <visual>
      <geometry>
        <mesh filename="package://ar10_description/meshes/Fingertip.STL" scale=".001 .001 .001" />
      </geometry>
      <origin xyz="0 -.0035 .00825" rpy="-1.57 1.57 0" />
      <material name="blue" />
    </visual>
    <collision>
      <geometry>
        <mesh filename="package://ar10_description/meshes/Fingertip.STL" scale=".001 .001 .001" />
      </geometry>
      <origin xyz="0 -.0035 .00825" rpy="-1.57 1.57 0" />
    </collision>
    <visual>
      <geometry>
        <mesh filename="package://ar10_description/meshes/Fingertip.STL" scale=".001 .001 .001" />
      </geometry>
      <origin xyz="-0.01 -.0035 .00825" rpy="-1.57 1.57 0" />
      <material name="blue" />
    </visual>
    <collision>
      <geometry>
        <mesh filename="package://ar10_description/meshes/Fingertip.STL" scale=".001 .001 .001" />
      </geometry>
      <origin xyz="-0.01 -.0035 .00825" rpy="-1.57 1.57 0" />
    </collision>
    <inertial>
      <mass value="0.008" />
      <inertia ixx="1.7e-07" ixy="0.0" ixz="0.0" iyy="2.8e-07" iyz="0.0" izz="4.2e-07" />
    </inertial>
  </link>
  <joint name="tip2" type="revolute">
    <axis xyz="-1 0 0" />
    <limit effort="0.42" lower="0.17" upper="1.57" velocity="0.5" />
    <parent link="finger2.1b" />
    <child link="finger2.1c" />
    <origin xyz="-.001 0 -.03" rpy="0 0 0" />
    <mimic joint="servo5" multiplier=".49" offset=".16" />
  </joint>
  <link name="fingertip2">
    <visual>
      <geometry>
        <mesh filename="package://ar10_description/meshes/fingertip-v9.STL" scale=".001 .001 .001" />
      </geometry>
      <origin xyz="-.009715 .011 -.015" rpy="1.57 0 0" />
      <material name="black" />
    </visual>
    <collision>
      <geometry>
        <mesh filename="package://ar10_description/meshes/fingertip-v9.STL" scale=".001 .001 .001" />
      </geometry>
      <origin xyz="-.009715 .011 -.015" rpy="1.57 0 0" />
    </collision>
    <inertial>
      <mass value="0.003" />
      <inertia ixx="3.5e-08" ixy="0.0" ixz="0.0" iyy="5.2e-08" iyz="0.0" izz="6.9e-08" />
    </inertial>
  </link>
  <joint name="ee2" type="fixed">
    <parent link="finger2.1c" />
    <child link="fingertip2" />
    <origin xyz="-.005 0 -.02" rpy="0 0 0" />
  </joint>
  <link name="finger3.1a">
    <visual>
      <geometry>
        <mesh filename="package://ar10_description/meshes/45mm 3 hole.STL" scale=".001 .001 .001" />
      </geometry>
      <origin xyz="0 -.00325 .0135" rpy="-1.57 1.57 0" />
      <material name="blue" />
    </visual>
    <collision>
      <geometry>
        <mesh filename="package://ar10_description/meshes/45mm 3 hole.STL" scale=".001 .001 .001" />
      </geometry>
      <origin xyz="0 -.00325 .0135" rpy="-1.57 1.57 0" />
    </collision>
    <visual>
      <geometry>
        <mesh filename="package://ar10_description/meshes/45mm 3 hole.STL" scale=".001 .001 .001" />
      </geometry>
      <origin xyz="-0.01 -.00325 .0135" rpy="-1.57 1.57 0" />
      <material name="blue" />
    </visual>
    <collision>
      <geometry>
        <mesh filename="package://ar10_description/meshes/45mm 3 hole.STL" scale=".001 .001 .001" />
      </geometry>
      <origin xyz="-0.01 -.00325 .0135" rpy="-1.57 1.57 0" />
    </collision>
    <inertial>
      <mass value="0.02" />
      <inertia ixx="7.1e-07" ixy="0.0" ixz="0.0" iyy="3.4e-06" iyz="0.0" izz="4e-06" />
    </inertial>
  </link>
  <joint name="servo6" type="revolute">
    <axis xyz="-1 0 0" />
    <limit effort="0.42" lower="0.17" upper="1.57" velocity="0.5" />
    <parent link="rb5" />
    <child link="finger3.1a" />
    <origin xyz="-.002 0 0" rpy="3.14 0 0" />
  </joint>
  <link name="finger3.1b">
    <visual>
      <geometry>
        <mesh filename="package://ar10_description/meshes/30mmROSFULL.STL" scale=".001 .001 .001" />
      </geometry>
      <origin xyz="0 -.0035 .0125" rpy="-1.57 1.57 0" />
      <material name="blue" />
    </visual>
    <collision>
      <geometry>
        <mesh filename="package://ar10_description/meshes/30mmROSFULL.STL" scale=".001 .001 .001" />
      </geometry>
      <origin xyz="0 -.0035 .0125" rpy="-1.57 1.57 0" />
    </collision>
    <visual>
      <geometry>
        <mesh filename="package://ar10_description/meshes/30mmROSFULL.STL" scale=".001 .001 .001" />
      </geometry>
      <origin xyz="-0.01 -.0035 .0125" rpy="-1.57 1.57 0" />
      <material name="blue" />
    </visual>
    <collision>
      <geometry>
        <mesh filename="package://ar10_description/meshes/30mmROSFULL.STL" scale=".001 .001 .001" />
      </geometry>
      <origin xyz="-0.01 -.0035 .0125" rpy="-1.57 1.57 0" />
    </collision>
    <inertial>
      <mass value="0.015" />
      <inertia ixx="5.3e-07" ixy="0.0" ixz="0.0" iyy="1.2e-06" iyz="0.0" izz="1.6e-06" />
    </inertial>
  </link>
  <joint name="servo7" type="revolute">
    <axis xyz="-1 0 0" />
    <limit effort="0.42" lower="0.17" upper="1.57" velocity="0.5" />
    <parent link="finger3.1a" />
    <child link="finger3.1b" />
    <origin xyz=".001 0 -.045" rpy="0 0 0" />
  </joint>
  <link name="finger3.1c">
    <visual>
      <geometry>
        <mesh filename="package://ar10_description/meshes/Fingertip.STL" scale=".001 .001 .001" />
      </geometry>
      <origin xyz="0 -.0035 .00825" rpy="-1.57 1.57 0" />
      <material name="blue" />
    </visual>
    <collision>
      <geometry>
        <mesh filename="package://ar10_description/meshes/Fingertip.STL" scale=".001 .001 .001" />
      </geometry>
      <origin xyz="0 -.0035 .00825" rpy="-1.57 1.57 0" />
    </collision>
    <visual>
      <geometry>
        <mesh filename="package://ar10_description/meshes/Fingertip.STL" scale=".001 .001 .001" />
      </geometry>
      <origin xyz="-0.01 -.0035 .00825" rpy="-1.57 1.57 0" />
      <material name="blue" />
    </visual>
    <collision>
      <geometry>
        <mesh filename="package://ar10_description/meshes/Fingertip.STL" scale=".001 .001 .001" />
      </geometry>
      <origin xyz="-0.01 -.0035 .00825" rpy="-1.57 1.57 0" />
    </collision>
    <inertial>
      <mass value="0.008" />
      <inertia ixx="1.7e-07" ixy="0.0" ixz="0.0" iyy="2.8e-07" iyz="0.0" izz="4.2e-07" />
    </inertial>
  </link>
  <joint name="tip3" type="revolute">
    <axis xyz="-1 0 0" />
    <limit effort="0.42" lower="0.17" upper="1.57" velocity="0.5" />
    <parent link="finger3.1b" />
    <child link="finger3.1c" />
    <origin xyz="-.001 0 -.03" rpy="0 0 0" />
    <mimic joint="servo7" multiplier=".49" offset=".16" />
  </joint>
  <link name="fingertip3">
    <visual>
      <geometry>
        <mesh filename="package://ar10_description/meshes/fingertip-v9.STL" scale=".001 .001 .001" />
      </geometry>
      <origin xyz="-.009715 .011 -.015" rpy="1.57 0 0" />
      <material name="black" />
    </visual>
    <collision>
      <geometry>
        <mesh filename="package://ar10_description/meshes/fingertip-v9.STL" scale=".001 .001 .001" />
      </geometry>
      <origin xyz="-.009715 .011 -.015" rpy="1.57 0 0" />
    </collision>
    <inertial>
      <mass value="0.003" />
      <inertia ixx="3.5e-08" ixy="0.0" ixz="0.0" iyy="5.2e-08" iyz="0.0" izz="6.9e-08" />
    </inertial>
  </link>
  <joint name="ee3" type="fixed">
    <parent link="finger3.1c" />
    <child link="fingertip3" />
    <origin xyz="-.005 0 -.02" rpy="0 0 0" />
  </joint>
  <link name="finger4.1a">
    <visual>
      <geometry>
        <mesh filename="package://ar10_description/meshes/45mm 3 hole.STL" scale=".001 .001 .001" />
      </geometry>
      <origin xyz="0 -.00325 .0135" rpy="-1.57 1.57 0" />
      <material name="blue" />
    </visual>
    <collision>
      <geometry>
        <mesh filename="package://ar10_description/meshes/45mm 3 hole.STL" scale=".001 .001 .001" />
      </geometry>
      <origin xyz="0 -.00325 .0135" rpy="-1.57 1.57 0" />
    </collision>
    <visual>
      <geometry>
        <mesh filename="package://ar10_description/meshes/45mm 3 hole.STL" scale=".001 .001 .001" />
      </geometry>
      <origin xyz="-0.01 -.00325 .0135" rpy="-1.57 1.57 0" />
      <material name="blue" />
    </visual>
    <collision>
      <geometry>
        <mesh filename="package://ar10_description/meshes/45mm 3 hole.STL" scale=".001 .001 .001" />
      </geometry>
      <origin xyz="-0.01 -.00325 .0135" rpy="-1.57 1.57 0" />
    </collision>
    <inertial>
      <mass value="0.02" />
      <inertia ixx="7.1e-07" ixy="0.0" ixz="0.0" iyy="3.4e-06" iyz="0.0" izz="4e-06" />
    </inertial>
  </link>
  <joint name="servo8" type="revolute">
    <axis xyz="-1 0 0" />
    <limit effort="0.42" lower="0.17" upper="1.57" velocity="0.5" />
    <parent link="rb7" />
    <child link="finger4.1a" />
    <origin xyz="-.002 0 0" rpy="3.14 0 0" />
  </joint>
  <link name="finger4.1b">
    <visual>
      <geometry>
        <mesh filename="package://ar10_description/meshes/30mmROSFULL.STL" scale=".001 .001 .001" />
      </geometry>
      <origin xyz="0 -.0035 .0125" rpy="-1.57 1.57 0" />
      <material name="blue" />
    </visual>
    <collision>
      <geometry>
        <mesh filename="package://ar10_description/meshes/30mmROSFULL.STL" scale=".001 .001 .001" />
      </geometry>
      <origin xyz="0 -.0035 .0125" rpy="-1.57 1.57 0" />
    </collision>
    <visual>
      <geometry>
        <mesh filename="package://ar10_description/meshes/30mmROSFULL.STL" scale=".001 .001 .001" />
      </geometry>
      <origin xyz="-0.01 -.0035 .0125" rpy="-1.57 1.57 0" />
      <material name="blue" />
    </visual>
    <collision>
      <geometry>
        <mesh filename="package://ar10_description/meshes/30mmROSFULL.STL" scale=".001 .001 .001" />
      </geometry>
      <origin xyz="-0.01 -.0035 .0125" rpy="-1.57 1.57 0" />
    </collision>
    <inertial>
      <mass value="0.015" />
      <inertia ixx="5.3e-07" ixy="0.0" ixz="0.0" iyy="1.2e-06" iyz="0.0" izz="1.6e-06" />
    </inertial>
  </link>
  <joint name="servo9" type="revolute">
    <axis xyz="-1 0 0" />
    <limit effort="0.42" lower="0.17" upper="1.57" velocity="0.5" />
    <parent link="finger4.1a" />
    <child link="finger4.1b" />
    <origin xyz=".001 0 -.045" rpy="0 0 0" />
  </joint>
  <link name="finger4.1c">
    <visual>
      <geometry>
        <mesh filename="package://ar10_description/meshes/Fingertip.STL" scale=".001 .001 .001" />
      </geometry>
      <origin xyz="0 -.0035 .00825" rpy="-1.57 1.57 0" />
      <material name="blue" />
    </visual>
    <collision>
      <geometry>
        <mesh filename="package://ar10_description/meshes/Fingertip.STL" scale=".001 .001 .001" />
      </geometry>
      <origin xyz="0 -.0035 .00825" rpy="-1.57 1.57 0" />
    </collision>
    <visual>
      <geometry>
        <mesh filename="package://ar10_description/meshes/Fingertip.STL" scale=".001 .001 .001" />
      </geometry>
      <origin xyz="-0.01 -.0035 .00825" rpy="-1.57 1.57 0" />
      <material name="blue" />
    </visual>
    <collision>
      <geometry>
        <mesh filename="package://ar10_description/meshes/Fingertip.STL" scale=".001 .001 .001" />
      </geometry>
      <origin xyz="-0.01 -.0035 .00825" rpy="-1.57 1.57 0" />
    </collision>
    <inertial>
      <mass value="0.008" />
      <inertia ixx="1.7e-07" ixy="0.0" ixz="0.0" iyy="2.8e-07" iyz="0.0" izz="4.2e-07" />
    </inertial>
  </link>
  <joint name="tip4" type="revolute">
    <axis xyz="-1 0 0" />
    <limit effort="0.42" lower="0.17" upper="1.57" velocity="0.5" />
    <parent link="finger4.1b" />
    <child link="finger4.1c" />
    <origin xyz="-.001 0 -.03" rpy="0 0 0" />
    <mimic joint="servo9" multiplier=".49" offset=".16" />
  </joint>
  <link name="fingertip4">
    <visual>
      <geometry>
        <mesh filename="package://ar10_description/meshes/fingertip-v9.STL" scale=".001 .001 .001" />
      </geometry>
      <origin xyz="-.009715 .011 -.015" rpy="1.57 0 0" />
      <material name="black" />
    </visual>
    <collision>
      <geometry>
        <mesh filename="package://ar10_description/meshes/fingertip-v9.STL" scale=".001 .001 .001" />
      </geometry>
      <origin xyz="-.009715 .011 -.015" rpy="1.57 0 0" />
    </collision>
    <inertial>
      <mass value="0.003" />
      <inertia ixx="3.5e-08" ixy="0.0" ixz="0.0" iyy="5.2e-08" iyz="0.0" izz="6.9e-08" />
    </inertial>
  </link>
  <joint name="ee4" type="fixed">
    <parent link="finger4.1c" />
    <child link="fingertip4" />
    <origin xyz="-.005 0 -.02" rpy="0 0 0" />
  </joint>
  <link name="thumb1">
    <visual>
      <geometry>
        <mesh filename="package://ar10_description/meshes/Thumb 1.STL" scale=".001 .001 .001" />
      </geometry>
      <origin xyz="0 -.02125 -.00325" rpy="0 0 1.57" />
      <material name="blue" />
    </visual>
    <collision>
      <geometry>
        <mesh filename="package://ar10_description/meshes/Thumb 1.STL" scale=".001 .001 .001" />
      </geometry>
      <origin xyz="0 -.02125 -.00325" rpy="0 0 1.57" />
    </collision>
    <inertial>
      <mass value="0.015" />
      <inertia ixx="6.3e-07" ixy="0.0" ixz="0.0" iyy="1.3e-06" iyz="0.0" izz="1.6e-06" />
    </inertial>
  </link>
  <joint name="servo0" type="revolute">
    <axis xyz="-1 0 0" />
    <limit effort="0.42" lower="0.85" upper="2.15" velocity="0.5" />
    <parent link="rb10" />
    <child link="thumb1" />
    <origin xyz="-.0015 0 0" rpy="-1.57 0 0" />
  </joint>
  <link name="thumb2">
    <visual>
      <geometry>
        <mesh filename="package://ar10_description/meshes/Thumb 2.STL" scale=".001 .001 .001" />
      </geometry>
      <origin xyz="0 -.0145 -.0095" rpy="0 0 1.57" />
      <material name="blue" />
    </visual>
    <collision>
      <geometry>
        <mesh filename="package://ar10_description/meshes/Thumb 2.STL" scale=".001 .001 .001" />
      </geometry>
      <origin xyz="0 -.0145 -.0095" rpy="0 0 1.57" />
    </collision>
    <inertial>
      <mass value="0.015" />
      <inertia ixx="6.3e-07" ixy="0.0" ixz="0.0" iyy="1.3e-06" iyz="0.0" izz="1.6e-06" />
    </inertial>
  </link>
  <joint name="thumb2joint" type="fixed">
    <parent link="thumb1" />
    <child link="thumb2" />
    <origin xyz=".0068 0 0" rpy="3.14 0 0" />
  </joint>
  <joint name="rb11_to_thumb2" type="fixed">
    <parent link="thumb2" />
    <child link="rb11" />
    <origin xyz="-.009 .0365 .0065" rpy="0 1.57 0" />
  </joint>
  <joint name="rb12_to_thumb2" type="fixed">
    <parent link="thumb2" />
    <child link="rb12" />
    <origin xyz="-.009 .0365 -.0065" rpy="0 1.57 0" />
  </joint>
  <link name="thumb3.1">
    <visual>
      <geometry>
        <mesh filename="package://ar10_description/meshes/Thumb 3-Rev2.STL" scale=".001 .001 .001" />
      </geometry>
      <origin xyz="0 .0125 -.0095" rpy="0 0 -1.57" />
      <material name="blue" />
    </visual>
    <collision>
      <geometry>
        <mesh filename="package://ar10_description/meshes/Thumb 3-Rev2.STL" scale=".001 .001 .001" />
      </geometry>
      <origin xyz="0 .0125 -.0095" rpy="0 0 -1.57" />
    </collision>
    <visual>
      <geometry>
        <mesh filename="package://ar10_description/meshes/Thumb 3-Rev2.STL" scale=".001 .001 .001" />
      </geometry>
      <origin xyz=".01 .0125 -.0095" rpy="0 0 -1.57" />
      <material name="blue" />
    </visual>
    <collision>
      <geometry>
        <mesh filename="package://ar10_description/meshes/Thumb 3-Rev2.STL" scale=".001 .001 .001" />
      </geometry>
      <origin xyz=".01 .0125 -.0095" rpy="0 0 -1.57" />
    </collision>
    <inertial>
      <mass value="0.02" />
      <inertia ixx="7.1e-07" ixy="0.0" ixz="0.0" iyy="3.4e-06" iyz="0.0" izz="4e-06" />
    </inertial>
  </link>
  <joint name="servo1" type="revolute">
    <axis xyz="1 0 0" />
    <limit effort="0.42" lower="0.34" upper="1.5" velocity="0.5" />
    <parent link="rb11" />
    <child link="thumb3.1" />
    <origin xyz=".002 0 0" rpy="3.14 0 0" />
  </joint>
  <link name="thumbtip">
    <visual>
      <geometry>
        <mesh filename="package://ar10_description/meshes/fingertip-v9.STL" scale=".001 .001 .001" />
      </geometry>
      <origin xyz=".009715 .005 .005" rpy="2.55 3.14 0" />
      <material name="black" />
    </visual>
    <collision>
      <geometry>
        <mesh filename="package://ar10_description/meshes/fingertip-v9.STL" scale=".001 .001 .001" />
      </geometry>
      <origin xyz=".009715 .005 .005" rpy="2.55 3.14 0" />
    </collision>
    <inertial>
      <mass value="0.003" />
      <inertia ixx="3.5e-08" ixy="0.0" ixz="0.0" iyy="5.2e-08" iyz="0.0" izz="6.9e-08" />
    </inertial>
  </link>
  <joint name="ee5" type="fixed">
    <parent link="thumb3.1" />
    <child link="thumbtip" />
    <origin xyz=".0048575 -.055 0" rpy="3.14 0 0" />
  </joint>
</robot>